Workbook

Sheet ABRIL
A1: ID | B1: SUCURSAL | C1: PROVEEDOR | D1: FACTURA | E1: FECHA | F1: TIPO DE FISCALIZACION | G1: RESPONSABLE | H1: INCIDENCIA | I1: TIPO DE ERROR | J1: OBSERVACIONES | K1: CLASIFICACION | L1: CLASIFICACION | M1: F COBRADA | N1: CLASIFICACION
A2: HIST_20260501_0 | B2: CENTRAL | C2: CAVA LUXOR | D2: 95389 | E2: 46113 | G2: SEÑOR CARLOS DE MANTENIMIENTO | H2: DIFERENCIA ENTRE CANTIDAD FISCALIZADA Y DOCUMENTO. | I2: =IF(G2="","",VLOOKUP(G2,REFERENCIA!$A$1:$B$15,2,0)) | L2: 2.58 | M2: 00095389
A3: HIST_20260501_1 | B3: CENTRAL | C3: ALIMENTOS VALLES DE ARAGUA | D3: 9560 | E3: 46119 | G3: NICOLE COLMENARES | H3: RECEPCIÓN SIN AUTORIZACIÓN DE CMF. | I3: =IF(G3="","",VLOOKUP(G3,REFERENCIA!$A$1:$B$15,2,0))
A4: HIST_20260501_2 | B4: CENTRAL | C4: ALIMENTOS VALLES DE ARAGUA | D4: 9561 | E4: 46119 | G4: NICOLE COLMENARES | H4: RECEPCIÓN SIN AUTORIZACIÓN DE CMF. | I4: =IF(G4="","",VLOOKUP(G4,REFERENCIA!$A$1:$B$15,2,0))
A5: HIST_20260501_3 | B5: CENTRAL | C5: PARMALAT | D5: #VALUE! | E5: 46119 | G5: BEATRIZ REYES | H5: DOCUMENTO NO LEGIBLE | I5: =IF(G5="","",VLOOKUP(G5,REFERENCIA!$A$1:$B$15,2,0))
A6: HIST_20260501_4 | B6: CENTRAL | C6: PARMALAT | D6: #VALUE! | E6: 46119 | G6: BEATRIZ REYES | H6: DOCUMENTO NO LEGIBLE | I6: =IF(G6="","",VLOOKUP(G6,REFERENCIA!$A$1:$B$15,2,0))
A7: HIST_20260501_5 | B7: CENTRAL | C7: PARMALAT | D7: #VALUE! | E7: 46119 | G7: BEATRIZ REYES | H7: DOCUMENTO NO LEGIBLE | I7: =IF(G7="","",VLOOKUP(G7,REFERENCIA!$A$1:$B$15,2,0))
A8: HIST_20260501_6 | B8: CENTRAL | C8: PARMALAT | D8: #VALUE! | E8: 46119 | G8: BEATRIZ REYES | H8: DOCUMENTO NO LEGIBLE | I8: =IF(G8="","",VLOOKUP(G8,REFERENCIA!$A$1:$B$15,2,0))
A9: HIST_20260501_7 | B9: CENTRAL | C9: PARMALAT | D9: #VALUE! | E9: 46119 | G9: BEATRIZ REYES | H9: DIFERENCIA ENTRE CANTIDAD FISCALIZADA Y DOCUMENTO. | I9: =IF(G9="","",VLOOKUP(G9,REFERENCIA!$A$1:$B$15,2,0)) | L9: 34.4
A10: HIST_20260501_8 | B10: CENTRAL | C10: PARMALAT | D10: #VALUE! | E10: 46119 | G10: BEATRIZ REYES | H10: DIFERENCIA ENTRE CANTIDAD FISCALIZADA Y DOCUMENTO. | I10: =IF(G10="","",VLOOKUP(G10,REFERENCIA!$A$1:$B$15,2,0)) | L10: 29.52
A11: HIST_20260501_9 | B11: CENTRAL | C11: FRUMIX | D11: 9336 | E11: 46120 | G11: PEDRO ALVARDO | H11: DIFERENCIA ENTRE CANTIDAD FISCALIZADA Y DOCUMENTO. | I11: =IF(G11="","",VLOOKUP(G11,REFERENCIA!$A$1:$B$15,2,0)) | L11: 92.29 | M11: N/A
A12: HIST_20260501_10 | B12: CENTRAL | C12: PATRONAS | D12: 482 | E12: 46121 | G12: ANGELO LIENDO | H12: RECEPCIÓN FUERA DE VISUAL / CON OBSTRUCCIÓN. | I12: =IF(G12="","",VLOOKUP(G12,REFERENCIA!$A$1:$B$15,2,0))
A13: HIST_20260501_11 | B13: CENTRAL | C13: H2O DE COCO | D13: 1259 | E13: 46122 | G13: ANGELO LIENDO | H13: DOCUMENTO NO LEGIBLE | I13: =IF(G13="","",VLOOKUP(G13,REFERENCIA!$A$1:$B$15,2,0))
A14: HIST_20260501_12 | B14: CENTRAL | C14: H2O DE COCO | D14: 1258 | E14: 46122 | G14: ANGELO LIENDO | H14: DOCUMENTO NO LEGIBLE | I14: =IF(G14="","",VLOOKUP(G14,REFERENCIA!$A$1:$B$15,2,0))
A15: HIST_20260501_13 | B15: CENTRAL | C15: ORO BLANCO | D15: 6194 | E15: 46125 | G15: NICOLE COLMENARES | H15: DOCUMENTO NO LEGIBLE | I15: =IF(G15="","",VLOOKUP(G15,REFERENCIA!$A$1:$B$15,2,0))
A16: HIST_20260501_14 | B16: CENTRAL | C16: ORO BLANCO | D16: 6192 | E16: 46125 | G16: NICOLE COLMENARES | H16: DOCUMENTO NO LEGIBLE | I16: =IF(G16="","",VLOOKUP(G16,REFERENCIA!$A$1:$B$15,2,0))
A17: HIST_20260501_15 | B17: CENTRAL | C17: ORO BLANCO | D17: 6193 | E17: 46125 | G17: NICOLE COLMENARES | H17: DOCUMENTO NO LEGIBLE | I17: =IF(G17="","",VLOOKUP(G17,REFERENCIA!$A$1:$B$15,2,0))
A18: HIST_20260501_16 | B18: CENTRAL | C18: FRUMIX | D18: 9409 | E18: 46126 | G18: BEATRIZ REYES | H18: DIFERENCIA ENTRE CANTIDAD FISCALIZADA Y DOCUMENTO. | I18: =IF(G18="","",VLOOKUP(G18,REFERENCIA!$A$1:$B$15,2,0)) | L18: 36.548
A19: HIST_20260501_17 | B19: CENTRAL | C19: FRUMIX | D19: 9410 | E19: 46126 | G19: BEATRIZ REYES | H19: DIFERENCIA ENTRE CANTIDAD FISCALIZADA Y DOCUMENTO. | I19: =IF(G19="","",VLOOKUP(G19,REFERENCIA!$A$1:$B$15,2,0)) | L19: 285.88
A20: HIST_20260501_18 | B20: CENTRAL | C20: FRUMIX | D20: 9408 | E20: 46126 | G20: BEATRIZ REYES | H20: DIFERENCIA ENTRE CANTIDAD FISCALIZADA Y DOCUMENTO. | I20: =IF(G20="","",VLOOKUP(G20,REFERENCIA!$A$1:$B$15,2,0)) | L20: 9.46
A21: HIST_20260501_19 | B21: CENTRAL | C21: FRUMIX | D21: 9409 | E21: 46126 | G21: BEATRIZ REYES | H21: NO SE INDICÓ DIFERENCIA AL DORSO DE LA FACTURA. | I21: =IF(G21="","",VLOOKUP(G21,REFERENCIA!$A$1:$B$15,2,0)) | L21: 1.87 | M21: 00048303
A22: HIST_20260501_20 | B22: CENTRAL | C22: CORVARA | D22: 30939 | E22: 46127 | G22: NICOLE COLMENARES | H22: DOCUMENTO NO LEGIBLE | I22: =IF(G22="","",VLOOKUP(G22,REFERENCIA!$A$1:$B$15,2,0))
A23: HIST_20260501_21 | B23: CENTRAL | C23: CORVARA | D23: 30938 | E23: 46127 | G23: NICOLE COLMENARES | H23: DOCUMENTO NO LEGIBLE | I23: =IF(G23="","",VLOOKUP(G23,REFERENCIA!$A$1:$B$15,2,0))
A24: HIST_20260501_22 | B24: CENTRAL | C24: CORVARA | D24: 30940 | E24: 46127 | G24: NICOLE COLMENARES | H24: DOCUMENTO NO LEGIBLE | I24: =IF(G24="","",VLOOKUP(G24,REFERENCIA!$A$1:$B$15,2,0))
A25: HIST_20260501_23 | B25: CENTRAL | C25: CORVARA | D25: 30937 | E25: 46127 | G25: NICOLE COLMENARES | H25: DOCUMENTO NO LEGIBLE | I25: =IF(G25="","",VLOOKUP(G25,REFERENCIA!$A$1:$B$15,2,0))
A26: HIST_20260501_24 | B26: CENTRAL | C26: OVOMAR | D26: 51320 | E26: 46127 | G26: LUIS BELLO | H26: NO SE INDICÓ DIFERENCIA AL DORSO DE LA FACTURA. | I26: =IF(G26="","",VLOOKUP(G26,REFERENCIA!$A$1:$B$15,2,0)) | L26: 15.93 | M26: N/A
A27: HIST_20260501_25 | B27: CENTRAL | C27: TUNAL | D27: 117568 | E27: 46128 | G27: BEATRIZ REYES | H27: DOCUMENTO NO LEGIBLE | I27: =IF(G27="","",VLOOKUP(G27,REFERENCIA!$A$1:$B$15,2,0))
A28: HIST_20260501_26 | B28: CENTRAL | C28: INDUSTRIAS NEVEX VEN CA | D28: 256 | E28: 46132 | G28: BEATRIZ REYES | H28: DIFERENCIA ENTRE CANTIDAD FISCALIZADA Y DOCUMENTO. | I28: =IF(G28="","",VLOOKUP(G28,REFERENCIA!$A$1:$B$15,2,0)) | L28: 5.37
A29: HIST_20260501_27 | B29: CENTRAL | C29: GRUPO SANT-PANINI, C.A | D29: 921 | E29: 46135 | G29: BEATRIZ REYES | H29: DIFERENCIA ENTRE CANTIDAD FISCALIZADA Y DOCUMENTO. | I29: =IF(G29="","",VLOOKUP(G29,REFERENCIA!$A$1:$B$15,2,0)) | L29: 156
A30: HIST_20260501_28 | B30: CENTRAL | C30: INDUSTRIA ALIMENTICIA NACIONAL DE CEREALES Y HARINAS, C.A. | D30: V1-16228 | E30: 46136 | G30: BEATRIZ REYES | H30: DIFERENCIA ENTRE CANTIDAD FISCALIZADA Y DOCUMENTO. | I30: =IF(G30="","",VLOOKUP(G30,REFERENCIA!$A$1:$B$15,2,0))
A31: HIST_20260501_29 | B31: CENTRAL | C31: INDUSTRIA ALIMENTICIA NACIONAL DE CEREALES Y HARINAS, C.A. | D31: V1-16226 | E31: 46136 | G31: BEATRIZ REYES | H31: DIFERENCIA ENTRE CANTIDAD FISCALIZADA Y DOCUMENTO. | I31: =IF(G31="","",VLOOKUP(G31,REFERENCIA!$A$1:$B$15,2,0))
A32: HIST_20260501_30 | B32: CENTRAL | C32: INDUSTRIA ALIMENTICIA NACIONAL DE CEREALES Y HARINAS, C.A. | D32: V1-16227 | E32: 46136 | G32: BEATRIZ REYES | H32: DIFERENCIA ENTRE CANTIDAD FISCALIZADA Y DOCUMENTO. | I32: =IF(G32="","",VLOOKUP(G32,REFERENCIA!$A$1:$B$15,2,0))
A33: HIST_20260501_31 | B33: CENTRAL | C33: REPRESENTACIONES SMSOL CENTRO, S.A | D33: 9145 | E33: 46139 | G33: BEATRIZ REYES | H33: RECEPCIÓN SIN AUTORIZACIÓN DE CMF. | I33: =IF(G33="","",VLOOKUP(G33,REFERENCIA!$A$1:$B$15,2,0))
A34: HIST_20260501_32 | B34: CENTRAL | C34: FABRICA DE PASTAS ALLEGRI, C.A | D34: #VALUE! | E34: 46140 | G34: BEATRIZ REYES | H34: RECEPCIÓN SIN AUTORIZACIÓN DE CMF. | I34: =IF(G34="","",VLOOKUP(G34,REFERENCIA!$A$1:$B$15,2,0))
A35: HIST_20260501_33 | B35: CENTRAL | C35: FABRICA DE PASTAS ALLEGRI, C.A | D35: #VALUE! | E35: 46140 | G35: BEATRIZ REYES | H35: RECEPCIÓN SIN AUTORIZACIÓN DE CMF. | I35: =IF(G35="","",VLOOKUP(G35,REFERENCIA!$A$1:$B$15,2,0))
A36: HIST_20260501_34 | B36: CENTRAL | C36: LACTEOS CORRALITO, F.P | D36: 672 | E36: 46134 | G36: PETER ARANDA | H36: DOCUMENTO NO LEGIBLE | I36: =IF(G36="","",VLOOKUP(G36,REFERENCIA!$A$1:$B$15,2,0))
A37: HIST_20260501_35 | B37: CENTRAL | C37: LACTEOS CORRALITO, F.P | D37: 673 | E37: 46134 | G37: PETER ARANDA | H37: DOCUMENTO NO LEGIBLE | I37: =IF(G37="","",VLOOKUP(G37,REFERENCIA!$A$1:$B$15,2,0))
A38: HIST_20260501_36 | B38: CENTRAL | C38: DISTRIBUIDORA Y BODEGON LOS PERICOS, C.A | D38: 167 | E38: 46140 | G38: PETER ARANDA | H38: DIFERENCIA ENTRE CANTIDAD FISCALIZADA Y DOCUMENTO. | I38: =IF(G38="","",VLOOKUP(G38,REFERENCIA!$A$1:$B$15,2,0)) | L38: 3.085
A39: HIST_20260501_37 | B39: CENTRAL | C39: INVERSIONES R.C.B 2025, C.A | D39: 104 | E39: 46140 | G39: PETER ARANDA | H39: DOCUMENTO NO LEGIBLE | I39: =IF(G39="","",VLOOKUP(G39,REFERENCIA!$A$1:$B$15,2,0))
A40: HIST_20260501_38 | B40: CENTRAL | C40: DISTRIBUIDORA Y BODEGON LOS PERICOS, C.A | D40: 167 | E40: 46140 | G40: PETER ARANDA | H40: DOCUMENTO NO LEGIBLE | I40: =IF(G40="","",VLOOKUP(G40,REFERENCIA!$A$1:$B$15,2,0))
...

Sheet REFERENCIA
A1: NÚMERO DE CONTROL O DOCUMENTO ERRÓNEO. | B1: TIPO A
A2: FALTA SELLO, FIRMA O CÉDULA. | B2: TIPO A
A3: DOCUMENTO NO LEGIBLE | B3: TIPO A
A4: DOCUMENTACIÓN ERRÓNEA | B4: TIPO B
A5: FISCALIZACIÓN A DESTIEMPO | B5: TIPO B
A6: PRODUCTO O SKU DUPLICADO. | B6: TIPO B
A7: RECEPCIÓN FUERA DE VISUAL / CON OBSTRUCCIÓN. | B7: TIPO B
A8: FISCALIZACIÓN CON USUARIO NO CORRESPONDIENTE | B8: TIPO C
A9: ERROR DE KG EN TARA. | B9: TIPO C
A10: PRODUCTO O SKU NO PERTENECE A LA RECEPCIÓN. | B10: TIPO C
A11: NO FISCALIZÓ UNO O VARIOS PRODUCTOS | B11: TIPO C
A12: NO SE INDICÓ DIFERENCIA AL DORSO DE LA FACTURA. | B12: TIPO D
... A15: NO SE COMPLETA EL PROCESO DE FISCALIZACION Y SE ELIMINA. | B15: TIPO E
