Workbook

Sheet Sheet1
A1: SUCURSAL | B1: PROVEEDOR | C1: FACTURA | D1: FECHA | E1: TIPO DE FISCALIZACION | F1: RESPONSABLE | G1: INCIDENCIA | H1: TIPO DE ERROR | I1: OBSERVACIONES | J1: CLASIFICACION | K1: CLASIFICACION | L1: F COBRADA | M1: CLASIFICACION
A2: CASTAÑO | B2: INDUSTRIAS LACTEAS VENEZOLANAS, C.A. (PARMALAT) | C2: 6200009978 | D2: 46083 | E2: RECEPCIÓN | F2: FERNANDO CABRERA | G2: PRODUCTO O SKU NO PERTENECE A LA RECEPCIÓN. | H2: =IF(F2="","",VLOOKUP(F2,REFERENCIA!$A$1:$B$14,2,0)) -> #N/A | I2: ERROR AL CARGAR SKU | K2: 17.07
A3: BARQUISIMETO | B3: ROMA, C.A. | C3: 253388 | D3: 46083 | E3: RECEPCIÓN | F3: RUBER RAMOS | G3: NÚMERO DE CONTROL O DOCUMENTO ERRÓNEO. | H3: =IF(F3="","",VLOOKUP(F3,REFERENCIA!$A$1:$B$14,2,0)) -> #N/A | I3: NRO DE FACTURA ERRONEO
A4: CASTAÑO | B4: ALIMENTOS PLAR COMERCIAL, C.A. | C4: 7242048879 | D4: 46084 | E4: RECEPCIÓN | F4: YORVIT ZORRILLA | G4: FALTA SELLO, FIRMA O CÉDULA. | H4: =IF(F4="","",VLOOKUP(F4,REFERENCIA!$A$1:$B$14,2,0)) -> #N/A | I4: FALTO NRO DE CEDULA DEL SPCP
A5: CASTAÑO | B5: GALLETERA ITALIA, C.A. | C5: 6269 | D5: 46084 | E5: RECEPCIÓN | F5: BARBARA ROMERO | G5: NÚMERO DE CONTROL O DOCUMENTO ERRÓNEO. | H5: =IF(F5="","",VLOOKUP(F5,REFERENCIA!$A$1:$B$14,2,0)) -> #N/A | I5: NRO DE FACTURA ERRONEO
A6: CASTAÑO | B6: CAVA LUXOR | C6: 3388 | D6: 46084 | E6: RECEPCIÓN | F6: BARBARA ROMERO | G6: PRODUCTO O SKU NO PERTENECE A LA RECEPCIÓN. | H6: =IF(F6="","",VLOOKUP(F6,REFERENCIA!$A$1:$B$14,2,0)) -> #N/A | I6: ERROR AL CARGAR SKU
A7: BARQUISIMETO | B7: SUPLIDORA EL VIGIA, SUVICA C.A. | C7: 5679 | D7: 46084 | E7: RECEPCIÓN | F7: REIDINSON MONTERO | G7: DOCUMENTACIÓN ERRÓNEA | H7: =IF(F7="","",VLOOKUP(F7,REFERENCIA!$A$1:$B$14,2,0)) -> #N/A | I7: SE CARGO LA FOTO ERRONEA
A8: BARQUISIMETO | B8: CORPORACION JSL, C.A. | C8: 90076096 | D8: 46085 | E8: RECEPCIÓN | F8: REIDINSON MONTERO | G8: NÚMERO DE CONTROL O DOCUMENTO ERRÓNEO. | H8: =IF(F8="","",VLOOKUP(F8,REFERENCIA!$A$1:$B$14,2,0)) -> #N/A | I8: NO DE FACTURA ERRONEO
A9: BARQUISIMETO | B9: ADOLFO'S VICAR, C.A. | C9: 13082 | D9: 46085 | E9: RECEPCIÓN | F9: REIDINSON MONTERO | G9: FALTA SELLO, FIRMA O CÉDULA. | H9: =IF(F9="","",VLOOKUP(F9,REFERENCIA!$A$1:$B$14,2,0)) -> #N/A | I9: FALTO NRO DE CEDULA DEL SPCP
A10: BARQUISIMETO | B10: ALIMENTOS POLAR COMERCIAL, C.A. | C10: 7790810569 | D10: 46085 | E10: RECEPCIÓN | F10: REIDINSON MONTERO | G10: NÚMERO DE CONTROL O DOCUMENTO ERRÓNEO. | H10: =IF(F10="","",VLOOKUP(F10,REFERENCIA!$A$1:$B$14,2,0)) -> #N/A | I10: NRO DE FACTURA ERRONEO
A11: BARQUISIMETO | B11: INVERSIONES LAS PATRONAS, 2024 C.A. | C11: 103 | D11: 46085 | E11: RECEPCIÓN | F11: REIDINSON MONTERO | G11: DIFERENCIA ENTRE CANTIDAD FISCALIZADA Y DOCUMENTO. | H11: =IF(F11="","",VLOOKUP(F11,REFERENCIA!$A$1:$B$14,2,0)) -> #N/A | I11: FALTANTE DE 1 KG DE PATILLA | K11: 0.59
A12: BARQUISIMETO | B12: ALIMENTOS DIFRESCA, C.A. | C12: 209239 | D12: 46086 | E12: RECEPCIÓN | F12: REIDINSON MONTERO | G12: NÚMERO DE CONTROL O DOCUMENTO ERRÓNEO. | H12: =IF(F12="","",VLOOKUP(F12,REFERENCIA!$A$1:$B$14,2,0)) -> #N/A | I12: NRO DE FACTURA ERRONEO
A13: CASTAÑO | B13: CORPORACION R3, C.A. | C13: 22631 | D13: 46086 | E13: DEVOLUCION | F13: DIEGO GUERRERO | G13: PRODUCTO O SKU NO PERTENECE A LA RECEPCIÓN. | H13: =IF(F13="","",VLOOKUP(F13,REFERENCIA!$A$1:$B$14,2,0)) -> #N/A | I13: ERROR AL CARGAR SKU
A14: CASTAÑO | B14: INVERSIONES DON DAVID NZ, C.A. | C14: 761 | D14: 46086 | E14: RECEPCIÓN | F14: DIEGO GUERRERO | G14: RECEPCIÓN SIN AUTORIZACIÓN DE CMF. | H14: =IF(F14="","",VLOOKUP(F14,REFERENCIA!$A$1:$B$14,2,0)) -> #N/A | I14: FISCALIZO SIN AUTORIZACION CMF
A15: CASTAÑO | B15: AGROPECUARIA LATIN FRUITS , C.A. | C15: 5578 | D15: 46087 | E15: RECEPCIÓN | F15: DIEGO GUERRERO | G15: PRODUCTO O SKU NO PERTENECE A LA RECEPCIÓN. | H15: =IF(F15="","",VLOOKUP(F15,REFERENCIA!$A$1:$B$14,2,0)) -> #N/A | I15: ERROR DE TARA
A16: BARQUISIMETO | B16: CAVA LUXOR | C16: 300008289 | D16: 46087 | E16: RECEPCIÓN | F16: REIDINSON MONTERO | G16: PRODUCTO O SKU DUPLICADO. | H16: =IF(F16="","",VLOOKUP(F16,REFERENCIA!$A$1:$B$14,2,0)) -> #N/A | I16: SKU DUPLICADO
A17: CASTAÑO | B17: CAVA LUXOR | D17: 46087 | E17: RECEPCIÓN | F17: FERNANDO CABRERA | G17: NO FISCALIZÓ UNO O VARIOS PRODUCTOS | H17: =IF(F17="","",VLOOKUP(F17,REFERENCIA!$A$1:$B$14,2,0)) -> #N/A | I17: NO FISCALIZO UNO O MAS PRODUCTOS | K17: 922.42
A18: CASTAÑO | B18: SUPLIDORA EL VIGIA, SUVICA C.A. | C18: 4275 | D18: 46090 | E18: RECEPCIÓN | F18: MARCOS GARCIA | G18: NÚMERO DE CONTROL O DOCUMENTO ERRÓNEO. | H18: =IF(F18="","",VLOOKUP(F18,REFERENCIA!$A$1:$B$14,2,0)) -> #N/A | I18: NRO DE CONTRL ERRONEO
A19: BARQUISIMETO | B19: COMERCIALIZADORA Y FERREAGRO SANTOS 7, C.A. | C19: 2465 | D19: 46090 | E19: RECEPCIÓN | F19: REIDINSON MONTERO | G19: NÚMERO DE CONTROL O DOCUMENTO ERRÓNEO. | H19: =IF(F19="","",VLOOKUP(F19,REFERENCIA!$A$1:$B$14,2,0)) -> #N/A | I19: NRO DE FACTURA ERRONEO
A20: BARQUISIMETO | B20: ADOLFO'S VICAR, C.A. | C20: 13115 | D20: 46090 | E20: RECEPCIÓN | F20: REIDINSON MONTERO | G20: DIFERENCIA ENTRE CANTIDAD FISCALIZADA Y DOCUMENTO. | H20: =IF(F20="","",VLOOKUP(F20,REFERENCIA!$A$1:$B$14,2,0)) -> #N/A | I20: FALTANTE DE 2 KL DE APIO , POR UN MONTO DE 2.84 $ | K20: 2.84
A21: CASTAÑO | B21: KC GLOBAL INT, C.A. | C21: 6250 | D21: 46092 | E21: RECEPCIÓN | F21: BARBARA ROMERO | G21: PRODUCTO O SKU DUPLICADO. | H21: =IF(F21="","",VLOOKUP(F21,REFERENCIA!$A$1:$B$14,2,0)) -> #N/A | I21: SKU DUPLICADO
A22: BARQUISIMETO | B22: CERVECERIA POLAR, C.A. | C22: 1630083787 | D22: 46092 | E22: RECEPCIÓN | F22: RUBER RAMOS | G22: NÚMERO DE CONTROL O DOCUMENTO ERRÓNEO. | H22: =IF(F22="","",VLOOKUP(F22,REFERENCIA!$A$1:$B$14,2,0)) -> #N/A | I22: NRO DE CONTROL ERRONEO
A23: BARQUISIMETO | B23: RUBROS SANARE C2, C.A. | C23: 23601 | D23: 46093 | E23: DEVOLUCION | F23: RUBER RAMOS | G23: ERROR DE KG EN TARA. | H23: =IF(F23="","",VLOOKUP(F23,REFERENCIA!$A$1:$B$14,2,0)) -> #N/A | I23: ERROR AL CARGA LA TARA SE COLOCO 2.4 KG Y SE RECIBIERON 2.2 KG LO CUAL GENERO UN FALTANTE DE 0.200 GR DE AGUACATE | K23: 1.41
A24: CASTAÑO | B24: ALIMENTOS HEINZ, C.A. | C24: 2218762 | D24: 46094 | E24: RECEPCIÓN | F24: FERNANDO CABRERA | G24: PRODUCTO O SKU DUPLICADO. | H24: =IF(F24="","",VLOOKUP(F24,REFERENCIA!$A$1:$B$14,2,0)) -> #N/A | I24: SKU DUPLICADO
A25: CASTAÑO | B25: ADOLFO'S VICAR, C.A. | C25: 13169 | D25: 46094 | E25: RECEPCIÓN | F25: DIEGO GUERRERO | G25: PRODUCTO O SKU DUPLICADO. | H25: =IF(F25="","",VLOOKUP(F25,REFERENCIA!$A$1:$B$14,2,0)) -> #N/A | I25: SKU DUPLICADO
A26: BARQUISIMETO | B26: CAVA LUXOR | C26: 300009123 | D26: 46094 | E26: RECEPCIÓN | F26: REIDINSON MONTERO | G26: PRODUCTO O SKU DUPLICADO. | H26: =IF(F26="","",VLOOKUP(F26,REFERENCIA!$A$1:$B$14,2,0)) -> #N/A | I26: SKU DUPLICADO
A27: CASTAÑO | B27: MUSACEUM, C.A. | C27: 3392 | D27: 46095 | E27: RECEPCIÓN | F27: MARCOS GARCIA | G27: RECEPCIÓN SIN AUTORIZACIÓN DE CMF. | H27: =IF(F27="","",VLOOKUP(F27,REFERENCIA!$A$1:$B$14,2,0)) -> #N/A | I27: FISCALIZO SIN AUTORIZACION CMF
A28: CASTAÑO | B28: CAVA LUXOR | C28: 3902 | D28: 46097 | E28: RECEPCIÓN | F28: NEIDY JASPE | G28: NÚMERO DE CONTROL O DOCUMENTO ERRÓNEO. | H28: =IF(F28="","",VLOOKUP(F28,REFERENCIA!$A$1:$B$14,2,0)) -> #N/A | I28: DOCUMENTACION ERRONEA
A29: CASTAÑO | B29: DISTRIBUIDORA DE ALIMENTOS BELLINO, C.A. | C29: 20873 | D29: 46097 | E29: RECEPCIÓN | F29: NEIDY JASPE | G29: PRODUCTO O SKU NO PERTENECE A LA RECEPCIÓN. | H29: =IF(F29="","",VLOOKUP(F29,REFERENCIA!$A$1:$B$14,2,0)) -> #N/A | I29: ERROR AL CARGAR SKU
A30: CASTAÑO | B30: ADOLFO'S VICAR, C.A. | C30: 13190 | D30: 46097 | E30: RECEPCIÓN | F30: BARBARA ROMERO | G30: RECEPCIÓN SIN AUTORIZACIÓN DE CMF. | H30: =IF(F30="","",VLOOKUP(F30,REFERENCIA!$A$1:$B$14,2,0)) -> #N/A | I30: FISCALIZO SIN AUTORIZACION CMF
A31: BARQUISIMETO | B31: ADOLFO'S VICAR, C.A. | C31: 24179 | D31: 46097 | E31: RECEPCIÓN | F31: REIDINSON MONTERO | G31: FALTA SELLO, FIRMA O CÉDULA. | H31: =IF(F31="","",VLOOKUP(F31,REFERENCIA!$A$1:$B$14,2,0)) -> #N/A | I31: FALTO SELLO DE4 LA SUCURSAL
A32: BARQUISIMETO | B32: I.T.C. DISTRIBUCIONES LOS LLANOS, C.A. | C32: JB30186 | D32: 46099 | E32: RECEPCIÓN | F32: REIDINSON MONTERO | G32: NÚMERO DE CONTROL O DOCUMENTO ERRÓNEO. | H32: =IF(F32="","",VLOOKUP(F32,REFERENCIA!$A$1:$B$14,2,0)) -> #N/A | I32: NRO DE FACTURA ERRONEO
A33: BARQUISIMETO | B33: EL TUNAL, C.A. | C33: 360220 | D33: 46099 | E33: RECEPCIÓN | F33: REIDINSON MONTERO | G33: NÚMERO DE CONTROL O DOCUMENTO ERRÓNEO. | H33: =IF(F33="","",VLOOKUP(F33,REFERENCIA!$A$1:$B$14,2,0)) -> #N/A | I33: NRO DE FACTURA ERRONEO
A34: BARQUISIMETO | B34: MOCASA MOLINOS CARABOBO, S.A. | C34: 1201406907 | D34: 46101 | E34: RECEPCIÓN | F34: REIDINSON MONTERO | G34: PRODUCTO O SKU DUPLICADO. | H34: =IF(F34="","",VLOOKUP(F34,REFERENCIA!$A$1:$B$14,2,0)) -> #N/A | I34: SKU DUPLICADO
A35: BARQUISIMETO | B35: INVERSIONES LAS PATRONAS 2024, C.A. | C35: 134 | D35: 46104 | E35: RECEPCIÓN | F35: REIDINSON MONTERO | G35: RECEPCIÓN FUERA DE VISUAL / CON OBSTRUCCIÓN. | H35: =IF(F35="","",VLOOKUP(F35,REFERENCIA!$A$1:$B$14,2,0)) -> #N/A | I35: RECEPCION FUERA DE VISUAL /CON OBSTRUCCION
A36: CASTAÑO | B36: TEQUEÑERIA EL TEQUEÑON, C.A. | C36: 23029 | D36: 46105 | E36: RECEPCIÓN | F36: FERNANDO CABRERA | G36: NÚMERO DE CONTROL O DOCUMENTO ERRÓNEO. | H36: =IF(F36="","",VLOOKUP(F36,REFERENCIA!$A$1:$B$14,2,0)) -> #N/A | I36: NRO DE FACTURA Y CONTROL ERRADO
A37: CASTAÑO | B37: ADOLFO'S VICAR, C.A. | C37: 13315 | D37: 46111 | E37: RECEPCIÓN | F37: EMISAEL QUERALES | G37: DIFERENCIA ENTRE CANTIDAD FISCALIZADA Y DOCUMENTO. | H37: =IF(F37="","",VLOOKUP(F37,REFERENCIA!$A$1:$B$14,2,0)) -> #N/A | I37: FALTANTE DE 200 GR DE COLIFLOR | K37: 0.88
A38: BARQUISIMETO | B38: EMBOTELLADORA DELCENTRO, C.A. | C38: 6003884 | D38: 46112 | E38: RECEPCIÓN | F38: REIDINSON MONTERO | G38: NÚMERO DE CONTROL O DOCUMENTO ERRÓNEO. | H38: =IF(F38="","",VLOOKUP(F38,REFERENCIA!$A$1:$B$14,2,0)) -> #N/A | I38: DOCUMENTACION ERRONEA
H39: =IF(F39="","",VLOOKUP(F39,REFERENCIA!$A$1:$B$14,2,0))
H40: =IF(F40="","",VLOOKUP(F40,REFERENCIA!$A$1:$B$14,2,0)) | K40: 945.21
...

Sheet REFERENCIA
A1: NÚMERO DE CONTROL O DOCUMENTO ERRÓNEO. | B1: TIPO A
A2: FALTA SELLO, FIRMA O CÉDULA. | B2: TIPO A
A3: DOCUMENTO NO LEGIBLE | B3: TIPO A
A4: DOCUMENTACIÓN ERRÓNEA | B4: TIPO B
A5: FISCALIZACIÓN A DESTIEMPO | B5: TIPO B
A6: PRODUCTO O SKU DUPLICADO. | B6: TIPO B
A7: RECEPCIÓN FUERA DE VISUAL / CON OBSTRUCCIÓN. | B7: TIPO B
A8: FISCALIZACIÓN CON USUARIO NO CORRESPONDIENTE | B8: TIPO C
A9: ERROR DE KG EN TARA. | B9: TIPO C
A10: PRODUCTO O SKU NO PERTENECE A LA RECEPCIÓN. | B10: TIPO C
A11: NO FISCALIZÓ UNO O VARIOS PRODUCTOS | B11: TIPO C
A12: NO SE INDICÓ DIFERENCIA AL DORSO DE LA FACTURA. | B12: TIPO D
... A14: RECEPCIÓN SIN AUTORIZACIÓN DE CMF. | B14: TIPO E
