Workbook

Sheet Sheet1
A1: SUCURSAL | B1: PROVEEDOR | C1: FACTURA | D1: FECHA | E1: TIPO FISCALIZACIÓN | F1: RESPONSABLE | G1: INCIDENCIA | H1: TIPO DE ERROR | I1: OBSERVACIÓN | J1: MONTO $
A2: CIRCULO MILITAR | B2: CAVA LUXOR | C2: *011701 | D2: 46113 | E2: RECEPCIÓN | F2: SPCP MACKENZY RAMIREZ | G2: NÚMERO DE CONTROL O DOCUMENTO ERRÓNEO. | H2: =IF(G2="","",VLOOKUP(G2,REFERENCIA!$A$1:$B$14,2,0)) -> TIPO A | I2: NÚMERO DE CONTROL CORRECTO: 300011701
A3: SAN DIEGO | B3: ECO CARNES, C.A. | C3: B000468 | D3: 46113 | E3: RECEPCIÓN | F3: GERENTE JHOAN VENA | G3: DOCUMENTACIÓN ERRÓNEA | H3: =IF(G3="","",VLOOKUP(G3,REFERENCIA!$A$1:$B$14,2,0)) -> TIPO B | I3: TRANSCRIBIO MAL EL NOMBRE DEL PRODUCTO EN FACTURA.
A4: CIRCULO MILITAR | B4: ECO CARNES, C.A. | C4: A012726 | D4: 46114 | E4: RECEPCIÓN | F4: SPCP CESAR HERNANDEZ | G4: FALTA SELLO, FIRMA O CÉDULA. | H4: =IF(G4="","",VLOOKUP(G4,REFERENCIA!$A$1:$B$14,2,0)) -> TIPO A | I4: FALTA LA CÉDULA DEL SPCP
A5: CIRCULO MILITAR | B5: PROCESADORA DE VEGETALES Y FRUTAS PROVEFRU, C.A. | C5: A021604 | D5: 46114 | E5: RECEPCIÓN | F5: SPCP CESAR HERNANDEZ | G5: FALTA SELLO, FIRMA O CÉDULA. | H5: =IF(G5="","",VLOOKUP(G5,REFERENCIA!$A$1:$B$14,2,0)) -> TIPO A | I5: FALTA LA CÉDULA DEL SPCP
A6: CIRCULO MILITAR | B6: DISTRIBUIDORA PARADIS FRESH C.A. | C6: 022926 | D6: 46114 | E6: RECEPCIÓN | F6: SPCP CESAR HERNANDEZ | G6: NO FISCALIZÓ UNO O VARIOS PRODUCTOS | H6: =IF(G6="","",VLOOKUP(G6,REFERENCIA!$A$1:$B$14,2,0)) -> TIPO C | I6: NO FISCALIZO EL COMPUESTO CEBOLLIN/CILANTRO, 8 UNIDADES, CON UN VALOR DE 3,62$ CADA UNA | J6: 28.96
A7: CIRCULO MILITAR | B7: AGROPECUARIA LATIN FRUITS C.A. | C7: 006046 | D7: 46115 | E7: RECEPCIÓN | F7: SPCP CESAR HERNANDEZ | G7: FALTA SELLO, FIRMA O CÉDULA. | H7: =IF(G7="","",VLOOKUP(G7,REFERENCIA!$A$1:$B$14,2,0)) -> TIPO A | I7: FALTA LA CÉDULA DEL SPCP
A8: CIRCULO MILITAR | B8: ECO CARNES, C.A. | C8: A012745 | D8: 46119 | E8: RECEPCIÓN | F8: SPCP CRISTAL CASTRO | G8: NO FISCALIZÓ UNO O VARIOS PRODUCTOS | H8: =IF(G8="","",VLOOKUP(G8,REFERENCIA!$A$1:$B$14,2,0)) -> TIPO C | I8: FALTO COLOCAR EL PESO DE LAS TARAS DEL TRASTE, 7 TARAS DE 2,3KG (16,1KG) | J8: 51.68
A9: SAN DIEGO | B9: C.P.A BEJUMA | C9: 0000072203 | D9: 46119 | E9: RECEPCIÓN | F9: SPCP NEYESKA DUQUE | G9: FALTA SELLO, FIRMA O CÉDULA. | H9: =IF(G9="","",VLOOKUP(G9,REFERENCIA!$A$1:$B$14,2,0)) -> TIPO A | I9: FALTA COLOCAR EL SELLO DE TIENDA
A10: SAN DIEGO | B10: LIOLITECH 2023, C.A. | C10: 0000733 | D10: 46119 | E10: RECEPCIÓN | F10: SUB GERENTE CARLOS ALMENAR | G10: NÚMERO DE CONTROL O DOCUMENTO ERRÓNEO. | H10: =IF(G10="","",VLOOKUP(G10,REFERENCIA!$A$1:$B$14,2,0)) -> TIPO A | I10: NÚMERO DE FACTURA CORRECTO: 00000733
A11: CIRCULO MILITAR | B11: ALMEN GROUP, C.A. | C11: 0166 | D11: 46119 | E11: RECEPCIÓN | F11: SPCP CRISTAL CASTRO | G11: NÚMERO DE CONTROL O DOCUMENTO ERRÓNEO. | H11: =IF(G11="","",VLOOKUP(G11,REFERENCIA!$A$1:$B$14,2,0)) -> TIPO A | I11: NÚMERO DE CONTROL CORRECTO: 00000166
A12: SAN DIEGO | B12: C.P.A BEJUMA | C12: 0000072202 | D12: 46119 | E12: RECEPCIÓN | F12: SPCP NEYESKA DUQUE | G12: FALTA SELLO, FIRMA O CÉDULA. | H12: =IF(G12="","",VLOOKUP(G12,REFERENCIA!$A$1:$B$14,2,0)) -> TIPO A | I12: FALTA COLOCAR EL SELLO DE TIENDA
A13: CIRCULO MILITAR | B13: HIDROPONIAS VENEZOLANAS, C.A. | C13: 20109432 | D13: 46120 | E13: RECEPCIÓN | F13: SPCP DANIHEL PALACIOS | G13: NO FISCALIZÓ UNO O VARIOS PRODUCTOS | H13: =IF(G13="","",VLOOKUP(G13,REFERENCIA!$A$1:$B$14,2,0)) -> TIPO C | I13: NO FISCALIZO EL "GRANO CHINO", 10 UNIDADES | J13: 23.7
A14: CIRCULO MILITAR | B14: HIDROPONIAS VENEZOLANAS, C.A. | C14: 20109433 | D14: 46120 | E14: RECEPCIÓN | F14: SPCP DANIHEL PALACIOS | G14: NO FISCALIZÓ UNO O VARIOS PRODUCTOS | H14: =IF(G14="","",VLOOKUP(G14,REFERENCIA!$A$1:$B$14,2,0)) -> TIPO C | I14: NO FISCALIZO LA "ENSALADA MIXTA C/CHERRY", 8 UNIDADES | J14: 34.24
A15: SAN DIEGO | B15: YEFFERSON MAY MORGADO CHACON | C15: 125164 | D15: 46120 | E15: RECEPCIÓN | F15: SUB GERENTE CARLOS ALMENAR | G15: NÚMERO DE CONTROL O DOCUMENTO ERRÓNEO. | H15: =IF(G15="","",VLOOKUP(G15,REFERENCIA!$A$1:$B$14,2,0)) -> TIPO A | I15: NÚMERO DE CONTROL CORRECTO: 000113164
A16: SAN DIEGO | B16: AGROPECUARIA PUNTA LARGA, C.A. | C16: R002987 | D16: 46120 | E16: RECEPCIÓN | F16: SUB GERENTE KAREN CABRERA | G16: DOCUMENTACIÓN ERRÓNEA | H16: =IF(G16="","",VLOOKUP(G16,REFERENCIA!$A$1:$B$14,2,0)) -> TIPO B | I16: LA IMAGEN DEL DORSO CARGADA NO PERTENECE A ESTA RECEPCIÓN
A17: CIRCULO MILITAR | B17: EL TUNAL, C.A. | C17: 0116589 | D17: 46120 | E17: RECEPCIÓN | F17: SPCP DANIHEL PALACIOS | G17: NO FISCALIZÓ UNO O VARIOS PRODUCTOS | H17: =IF(G17="","",VLOOKUP(G17,REFERENCIA!$A$1:$B$14,2,0)) -> TIPO C | I17: NO FISCALIZO LOS "HUEVOS ESTUCHADO EL TUNAL 15UND CAJA 20", 15 CAJAS | J17: 1185
A18: CIRCULO MILITAR | B18: PROCESADORA DE VEGETALES Y FRUTAS PROVEFRU, C.A. | C18: A021639 | D18: 46121 | E18: RECEPCIÓN | F18: SPCP DANIHEL PALACIOS | G18: PRODUCTO O SKU DUPLICADO. | H18: =IF(G18="","",VLOOKUP(G18,REFERENCIA!$A$1:$B$14,2,0)) -> TIPO B | I18: SKU DE LA ESPINACA DUPLICADO
A19: CIRCULO MILITAR | B19: PROCESADORA DE VEGETALES Y FRUTAS PROVEFRU, C.A. | C19: A021639 | D19: 46121 | E19: RECEPCIÓN | F19: SPCP DANIHEL PALACIOS | G19: NO FISCALIZÓ UNO O VARIOS PRODUCTOS | H19: =IF(G19="","",VLOOKUP(G19,REFERENCIA!$A$1:$B$14,2,0)) -> TIPO C | I19: NO FISCALIZO EL "CEBOLLIN DE 120GR", 5 UNIDADES | J19: 8.85
A20: CIRCULO MILITAR | B20: FRUMIX,C.A. | C20: 00009342 | D20: 46121 | E20: RECEPCIÓN | F20: SPCP DANIHEL PALACIOS | G20: PRODUCTO O SKU DUPLICADO. | H20: =IF(G20="","",VLOOKUP(G20,REFERENCIA!$A$1:$B$14,2,0)) -> TIPO B | I20: SKU DE LA MANZANA PINK LADY, MANZANA ROJA Y LA UVA ROJA DUPLICADO
A21: CIRCULO MILITAR | B21: FRUMIX,C.A. | C21: 00009342 | D21: 46121 | E21: RECEPCIÓN | F21: SPCP DANIHEL PALACIOS | G21: DIFERENCIA ENTRE CANTIDAD FISCALIZADA Y DOCUMENTO. | H21: =IF(G21="","",VLOOKUP(G21,REFERENCIA!$A$1:$B$14,2,0)) -> TIPO D | I21: ERROR EN CODIGO DE PRODUCTO COLOCADO EN NOTA
A22: CIRCULO MILITAR | B22: FRUMIX,C.A. | C22: 00009342 | D22: 46121 | E22: RECEPCIÓN | F22: SPCP DANIHEL PALACIOS | G22: NO FISCALIZÓ UNO O VARIOS PRODUCTOS | H22: =IF(G22="","",VLOOKUP(G22,REFERENCIA!$A$1:$B$14,2,0)) -> TIPO C | I22: LA RECEPCIÓN SE HABIA DOCUMENTADO FALTANDO AGREGAR LOS SIGUIENTES PRODUCTOS: GRANADA IMPORTADA (11,5KG) 264,6$, MANZANA PINK LADY (103,2KG) 695,6$ Y MANZANA RED (124,4KG) 888,2$ | J22: 1848.4
A23: CIRCULO MILITAR | B23: MUSACEUM C.A. | C23: 003796 | D23: 46121 | E23: RECEPCIÓN | F23: SPCP DANIHEL PALACIOS | G23: NÚMERO DE CONTROL O DOCUMENTO ERRÓNEO. | H23: =IF(G23="","",VLOOKUP(G23,REFERENCIA!$A$1:$B$14,2,0)) -> TIPO A | I23: NÚMERO DE CONTROL CORRECTO: 0000004529
A24: SAN DIEGO | B24: RUBROS SANARE C2, C.A. | C24: 0002310 | D24: 46121 | E24: RECEPCIÓN | F24: SPCP NELSON DE FREITAS | G24: NO FISCALIZÓ UNO O VARIOS PRODUCTOS | H24: =IF(G24="","",VLOOKUP(G24,REFERENCIA!$A$1:$B$14,2,0)) -> TIPO C | I24: NO FISCALIZO EL ÚLTIMO PESAJE DE PIMENTON, 119,8KG | J24: 803.9
A25: SAN DIEGO | B25: PRODUCTOS ALIMEX C.A | C25: 0038156 | D25: 46121 | E25: RECEPCIÓN | F25: SUB GERENTE YELITXA ANGULO | G25: NÚMERO DE CONTROL O DOCUMENTO ERRÓNEO. | H25: =IF(G25="","",VLOOKUP(G25,REFERENCIA!$A$1:$B$14,2,0)) -> TIPO A | I25: NÚMERO DE CONTROL CORRECTO: 0039156
A26: CIRCULO MILITAR | B26: CAVA LUXOR | C26: *4853 | D26: 46122 | E26: RECEPCIÓN | F26: SPCP CRISTAL CASTRO | G26: ERROR DE KG EN TARA. | H26: =IF(G26="","",VLOOKUP(G26,REFERENCIA!$A$1:$B$14,2,0)) -> TIPO C | I26: FALTO AGREGAR EL PESO DE LAS TARAS DEL QUESO GUAYANES, 25 TARAS DE 1KG (25KG) | J26: 185.75
A27: SAN DIEGO | B27: AGROPECUARIA LATIN FRUITS C.A. | C27: 006136 | D27: 46122 | E27: RECEPCIÓN | F27: SUB GERENTE CARLOS ALMENAR | G27: NÚMERO DE CONTROL O DOCUMENTO ERRÓNEO. | H27: =IF(G27="","",VLOOKUP(G27,REFERENCIA!$A$1:$B$14,2,0)) -> TIPO A | I27: NÚMERO DE CONTROL CORRECTO: 0000009566
A28: CIRCULO MILITAR | B28: MUSACEUM C.A. | C28: 003840 | D28: 46123 | E28: RECEPCIÓN | F28: SPCP JESUS PACHECO | G28: NÚMERO DE CONTROL O DOCUMENTO ERRÓNEO. | H28: =IF(G28="","",VLOOKUP(G28,REFERENCIA!$A$1:$B$14,2,0)) -> TIPO A | I28: NÚMERO DE CONTROL CORRECTO: 0000004584
A29: CIRCULO MILITAR | B29: PROCESADORA DE VEGETALES Y FRUTAS PROVEFRU, C.A. | C29: A021660 | D29: 46125 | E29: RECEPCIÓN | F29: SPCP MACKENZY RAMIREZ | G29: NO FISCALIZÓ UNO O VARIOS PRODUCTOS | H29: =IF(G29="","",VLOOKUP(G29,REFERENCIA!$A$1:$B$14,2,0)) -> TIPO C | I29: NO FISCALIZO LA "ALBAHACA DE 60GR" 5 UNIDADES, VALOR TOTAL 8,85$ | J29: 8.85
A30: SAN DIEGO | B30: SUPLIDORA EL VIGIA, COMPAÑIA ANONIMA(SUVICA) | C30: 006007 | D30: 46125 | E30: RECEPCIÓN | F30: SPCP IRENE AULAR | G30: NÚMERO DE CONTROL O DOCUMENTO ERRÓNEO. | H30: =IF(G30="","",VLOOKUP(G30,REFERENCIA!$A$1:$B$14,2,0)) -> TIPO A | I30: NÚMERO DE CONTROL CORRECTO: 00056507
A31: SAN DIEGO | B31: YEFFERSON MAY MORGADO CHACON | C31: 125255 | D31: 46125 | E31: RECEPCIÓN | F31: SUB GERENTE CARLOS ALMENAR | G31: FALTA SELLO, FIRMA O CÉDULA. | H31: =IF(G31="","",VLOOKUP(G31,REFERENCIA!$A$1:$B$14,2,0)) -> TIPO A | I31: FALTA LA FIRMA DEL SPCP, EL SELLO DE LA TIENDA Y LA CÉDULA DEL SPCP
A32: CIRCULO MILITAR | B32: LA CARIDAD C.A. | C32: E40920 | D32: 46126 | E32: RECEPCIÓN | F32: SPCP CESAR HERNANDEZ | G32: NÚMERO DE CONTROL O DOCUMENTO ERRÓNEO. | H32: =IF(G32="","",VLOOKUP(G32,REFERENCIA!$A$1:$B$14,2,0)) -> TIPO A | I32: NÚMERO DE CONTROL CORRECTO: 00468282
A33: CIRCULO MILITAR | B33: PEPSI COLA VENEZUELA, C.A./S.T.C POLAR C.A | C33: 201245738 | D33: 46126 | E33: RECEPCIÓN | F33: SPCP MACKENZY RAMIREZ | G33: DOCUMENTACIÓN ERRÓNEA | H33: =IF(G33="","",VLOOKUP(G33,REFERENCIA!$A$1:$B$14,2,0)) -> TIPO B | I33: FALTO CARGAR IMAGEN DEL DORSO
A34: CIRCULO MILITAR | B34: ALIMENTOS POLAR COMERCIAL C.A. | C34: 7242078136 | D34: 46126 | E34: RECEPCIÓN | F34: SPCP MACKENZY RAMIREZ | G34: PRODUCTO O SKU NO PERTENECE A LA RECEPCIÓN. | H34: =IF(G34="","",VLOOKUP(G34,REFERENCIA!$A$1:$B$14,2,0)) -> TIPO C | I34: EL "VINAGRE BLANCO DE 1L" NO PERTENECE A ESTA RECEPCIÓN
A35: SAN DIEGO | B35: DISTRIBUIDORA GADUCA C.A | C35: 00117243 | D35: 46127 | E35: RECEPCIÓN | F35: SUB GERENTE YELITXA ANGULO | G35: NÚMERO DE CONTROL O DOCUMENTO ERRÓNEO. | H35: =IF(G35="","",VLOOKUP(G35,REFERENCIA!$A$1:$B$14,2,0)) -> TIPO A | I35: NÚMERO DE FACTURA CORRECTO: D000117243
A36: CIRCULO MILITAR | B36: CAVA LUXOR | C36: *013052 | D36: 46127 | E36: RECEPCIÓN | F36: SPCP MACKENZY RAMIREZ | G36: NÚMERO DE CONTROL O DOCUMENTO ERRÓNEO. | H36: =IF(G36="","",VLOOKUP(G36,REFERENCIA!$A$1:$B$14,2,0)) -> TIPO A | I36: NÚMERO DE CONTROL CORRECTO: 300013052
A37: CIRCULO MILITAR | B37: YEFFERSON MAY MORGADO CHACON | C37: 125489 | D37: 46129 | E37: RECEPCIÓN | F37: SPCP CESAR HERNANDEZ | G37: NÚMERO DE CONTROL O DOCUMENTO ERRÓNEO. | H37: =IF(G37="","",VLOOKUP(G37,REFERENCIA!$A$1:$B$14,2,0)) -> TIPO A | I37: número de factura correcto: 125489
A38: SAN DIEGO | B38: CAVA LUXOR | C38: *3000013075 | D38: 46129 | E38: RECEPCIÓN | F38: SUB GERENTE CARLOS ALMENAR | G38: NÚMERO DE CONTROL O DOCUMENTO ERRÓNEO. | H38: =IF(G38="","",VLOOKUP(G38,REFERENCIA!$A$1:$B$14,2,0)) -> TIPO A | I38: NÚMERO DE CONTROL CORRECTO: 300013075
A39: SAN DIEGO | B39: EMBUTIDOS MOVILLA, C.A. | C39: 00159402 | D39: 46133 | E39: RECEPCIÓN | F39: SUB GERENTE YELITXA ANGULO | G39: NÚMERO DE CONTROL O DOCUMENTO ERRÓNEO. | H39: =IF(G39="","",VLOOKUP(G39,REFERENCIA!$A$1:$B$14,2,0)) -> TIPO A | I39: NÚMERO DE FACTURA CORRECTO: 00159482
A40: CIRCULO MILITAR | B40: CAVA LUXOR | C40: *300013784 | D40: 46133 | E40: RECEPCIÓN | F40: SPCP DANIHEL PALACIOS | G40: ERROR DE KG EN TARA. | H40: =IF(G40="","",VLOOKUP(G40,REFERENCIA!$A$1:$B$14,2,0)) -> TIPO C | I40: NO AGREGO EL PESO DE LAS TARAS AL QUESO LLANERO, 12 TARAS DE 2,6KG (31,2KG) | J40: 309.2
...

Sheet REFERENCIA
A1: NÚMERO DE CONTROL O DOCUMENTO ERRÓNEO. | B1: TIPO A
A2: FALTA SELLO, FIRMA O CÉDULA. | B2: TIPO A
A3: DOCUMENTO NO LEGIBLE | B3: TIPO A
A4: DOCUMENTACIÓN ERRÓNEA | B4: TIPO B
A5: FISCALIZACIÓN A DESTIEMPO | B5: TIPO B
A6: PRODUCTO O SKU DUPLICADO. | B6: TIPO B
A7: RECEPCIÓN FUERA DE VISUAL / CON OBSTRUCCIÓN. | B7: TIPO B
A8: FISCALIZACIÓN CON USUARIO NO CORRESPONDIENTE | B8: TIPO C
A9: ERROR DE KG EN TARA. | B9: TIPO C
A10: PRODUCTO O SKU NO PERTENECE A LA RECEPCIÓN. | B10: TIPO C
A11: NO FISCALIZÓ UNO O VARIOS PRODUCTOS | B11: TIPO C
A12: NO SE INDICÓ DIFERENCIA AL DORSO DE LA FACTURA. | B12: TIPO D
... A14: RECEPCIÓN SIN AUTORIZACIÓN DE CMF. | B14: TIPO E
