Workbook

Sheet Sheet1
A1: SUCURSAL | B1: PROVEEDOR | C1: FACTURA | D1: FECHA | E1: TIPO FISCALIZACIÓN | F1: RESPONSABLE | G1: INCIDENCIA | H1: TIPO DE ERROR | I1: OBSERVACIÓN | J1: MONTO $
A2: TUCACAS | B2: ADOLFO'S VICAR, C.A | C2: 13335 | D2: 46113 | E2: RECEPCION | F2: GERENTE JUAN MEZA | G2: RECEPCIÓN SIN AUTORIZACIÓN DE CMF. | H2: =IF(G2="","",VLOOKUP(G2,REFERENCIA!$A$1:$B$14,2,0)) -> TIPO E | I2: RECEPCION SIN AUTORIZACION DE CMF
A3: EL BOSQUE | B3: FRUMIX, C.A | C3: 9271 | D3: 46113 | E3: RECEPCION | F3: SUB VIRGILIO ARAUJO | G3: NÚMERO DE CONTROL O DOCUMENTO ERRÓNEO. | H3: =IF(G3="","",VLOOKUP(G3,REFERENCIA!$A$1:$B$14,2,0)) -> TIPO A | I3: NUMERO DE CONTROL INCORRECTO
A4: EL BOSQUE | B4: ADOLFO'S VICAR, C.A | C4: 13327 | D4: 46113 | E4: RECEPCION | F4: SUB VIRGILIO ARAUJO | G4: ERROR DE KG EN TARA. | H4: =IF(G4="","",VLOOKUP(G4,REFERENCIA!$A$1:$B$14,2,0)) -> TIPO C | I4: ERROR EN TARA, 2.6KG DE CILANTRO | J4: 3.9
A5: TUCACAS | B5: INVERSIONES LAS PATRONAS, C.A | C5: 246 | D5: 46113 | E5: RECEPCION | F5: SUB GENESIS COBOS | G5: ERROR DE KG EN TARA. | H5: =IF(G5="","",VLOOKUP(G5,REFERENCIA!$A$1:$B$14,2,0)) -> TIPO C | I5: ERROR EN TARA, 2.6KG DE GUAYABA | J5: 1.69
A6: NAGUANAGUA | B6: ECO CARNES, C.A | C6: 12706 | D6: 46113 | E6: RECEPCION | F6: GERENTE ANGEL LARREAL | G6: DIFERENCIA ENTRE CANTIDAD FISCALIZADA Y DOCUMENTO. | H6: =IF(G6="","",VLOOKUP(G6,REFERENCIA!$A$1:$B$14,2,0)) -> TIPO D | I6: ERROR EN EVA, 32.4KG | J6: 57.1
A7: TUCACAS | B7: ADOLFO'S VICAR, C.A | C7: 13335 | D7: 46113 | E7: RECEPCION | F7: GERENTE JUAN MEZA | G7: NO FISCALIZÓ UNO O VARIOS PRODUCTOS | H7: =IF(G7="","",VLOOKUP(G7,REFERENCIA!$A$1:$B$14,2,0)) -> TIPO C | I7: NO FISCALIZÓ UNO O MAS PRODUCTOS, PAPA LAVADA 20KG, LECHUGA ROMANA 71.6KG| | J7: 86.86 | M7: AMARILLO | N7: RECUPERADO
A8: EL BOSQUE | B8: AGROPECUARIA PUNTA LARGA, C.A| | C8: 2966 | D8: 46114 | E8: RECEPCION | F8: SUB VICTOR SALCEDO | G8: DIFERENCIA ENTRE CANTIDAD FISCALIZADA Y DOCUMENTO. | H8: =IF(G8="","",VLOOKUP(G8,REFERENCIA!$A$1:$B$14,2,0)) -> TIPO D | I8: FALTANTE DE 3KG DE CAMBUR | J8: 4.35 | M8: VERDE | N8: COBRADO
A9: EL BOSQUE | B9: VERONA EMBUTIDOS, C.A | C9: 345 | D9: 46114 | E9: RECEPCION | F9: SUB SUGGEY CASTRO | G9: NO FISCALIZÓ UNO O VARIOS PRODUCTOS | H9: =IF(G9="","",VLOOKUP(G9,REFERENCIA!$A$1:$B$14,2,0)) -> TIPO C | I9: NO FISCALIZÓ, 28.8KG DE CHULETA | J9: 167.04
A10: TUCACAS | B10: CERVECERIA REGIONAL | C10: 222162 | D10: 46115 | E10: RECEPCION | F10: GERENTE JUAN MEZA | G10: RECEPCIÓN SIN AUTORIZACIÓN DE CMF. | H10: =IF(G10="","",VLOOKUP(G10,REFERENCIA!$A$1:$B$14,2,0)) -> TIPO E | I10: RECEPCION SIN AUTORIZACION DE CMF
A11: TUCACAS | B11: DISTRIBUIDORA VPA, C.A | C11: 871 | D11: 46115 | E11: RECEPCION | F11: GERENTE JUAN MEZA | G11: RECEPCIÓN SIN AUTORIZACIÓN DE CMF. | H11: =IF(G11="","",VLOOKUP(G11,REFERENCIA!$A$1:$B$14,2,0)) -> TIPO E | I11: RECEPCION SIN AUTORIZACION DE CMF
A12: TUCACAS | B12: HIELO BARQUISIMEMTO, C,A | C12: 30426 | D12: 46115 | E12: RECEPCION | F12: SUB CARLOS PARACO | G12: RECEPCIÓN SIN AUTORIZACIÓN DE CMF. | H12: =IF(G12="","",VLOOKUP(G12,REFERENCIA!$A$1:$B$14,2,0)) -> TIPO E | I12: RECEPCION SIN AUTORIZACION DE CMF
A13: TUCACAS | B13: AGROPECUARIA LATIN FRUITS, C.A | C13: 6067 | D13: 46115 | E13: RECEPCION | F13: GERENTE JUAN MEZA | G13: RECEPCIÓN SIN AUTORIZACIÓN DE CMF. | H13: =IF(G13="","",VLOOKUP(G13,REFERENCIA!$A$1:$B$14,2,0)) -> TIPO E | I13: RECEPCION SIN AUTORIZACION DE CMF
A14: TUCACAS | B14: AGROPECUARIA LATIN FRUITS, C.A | C14: 6040 | D14: 46115 | E14: RECEPCION | F14: GERENTE JUAN MEZA | G14: RECEPCIÓN SIN AUTORIZACIÓN DE CMF. | H14: =IF(G14="","",VLOOKUP(G14,REFERENCIA!$A$1:$B$14,2,0)) -> TIPO E | I14: RECEPCION SIN AUTORIZACION DE CMF
A15: TUCACAS | B15: AGROPECUARIA LATIN FRUITS, C.A | C15: 6040 | D15: 46115 | E15: RECEPCION | F15: GERENTE JUAN MEZA | G15: FISCALIZACIÓN A DESTIEMPO | I15: FISCALIZACION A DESTIEMPO
A16: NAGUANAGUA | B16: SAPORI, C.A | C16: 36561 | D16: 46120 | E16: RECEPCION | F16: SUB REINALDO SILVA | G16: FISCALIZACIÓN A DESTIEMPO | H16: =IF(G16="","",VLOOKUP(G16,REFERENCIA!$A$1:$B$14,2,0)) -> TIPO B | I16: FISCALIZACION A DESTIEMPO
A17: NAGUANAGUA | B17: COMERCIALIZADORA Y FERREAGRO SANTOS 7 | C17: 2646 | D17: 46120 | E17: RECEPCION | F17: SUB REINALDO SILVA | G17: FISCALIZACIÓN A DESTIEMPO | H17: =IF(G17="","",VLOOKUP(G17,REFERENCIA!$A$1:$B$14,2,0)) -> TIPO B | I17: FISCALIZACION A DESTIEMPO
A18: NAGUANAGUA | B18: ALIMENTOS POLAR COMERCIAL, C.A | C18: 8031304345 | D18: 46120 | E18: RECEPCION | F18: PCP ANDRES ARCILA | G18: FISCALIZACIÓN A DESTIEMPO | H18: =IF(G18="","",VLOOKUP(G18,REFERENCIA!$A$1:$B$14,2,0)) -> TIPO B | I18: FISCALIZACION A DESTIEMPO
A19: NAGUANAGUA | B19: CAVA LUXOR | C19: 3000011999 | D19: 46120 | E19: RECEPCION | F19: SUB STEVEN SERVET | G19: FISCALIZACIÓN A DESTIEMPO | H19: =IF(G19="","",VLOOKUP(G19,REFERENCIA!$A$1:$B$14,2,0)) -> TIPO B | I19: FISCALIZACION A DESTIEMPO
A20: NAGUANAGUA | B20: CAVA LUXOR | C20: 300001885 | D20: 46120 | E20: RECEPCION | F20: SUB STEVEN SERVET | G20: FISCALIZACIÓN A DESTIEMPO | H20: =IF(G20="","",VLOOKUP(G20,REFERENCIA!$A$1:$B$14,2,0)) -> TIPO B | I20: FISCALIZACION A DESTIEMPO
A21: NAGUANAGUA | B21: SERVICIOS SEPORVEN, C.A | C21: 3005 | D21: 46120 | E21: RECEPCION | F21: PCP JOSE MALUENGA | G21: FISCALIZACIÓN A DESTIEMPO | H21: =IF(G21="","",VLOOKUP(G21,REFERENCIA!$A$1:$B$14,2,0)) -> TIPO B | I21: FISCALIZACION A DESTIEMPO
A22: NAGUANAGUA | B22: CAVA LUXOR | C22: 3000012114 | D22: 46120 | E22: RECEPCION | F22: SUB STEVEN SERVET | G22: FISCALIZACIÓN A DESTIEMPO | H22: =IF(G22="","",VLOOKUP(G22,REFERENCIA!$A$1:$B$14,2,0)) -> TIPO B | I22: FISCALIZACION A DESTIEMPO
A23: NAGUANAGUA | B23: HATO EL OSO, C.A | C23: 50985 | D23: 46120 | E23: RECEPCION | F23: SUB STEVEN SERVET | G23: FISCALIZACIÓN A DESTIEMPO | H23: =IF(G23="","",VLOOKUP(G23,REFERENCIA!$A$1:$B$14,2,0)) -> TIPO B | I23: FISCALIZACION A DESTIEMPO
A24: NAGUANAGUA | B24: CAVA LUXOR | C24: 4747 | D24: 46120 | E24: RECEPCION | F24: SUB STEVEN SERVET | G24: FISCALIZACIÓN A DESTIEMPO | H24: =IF(G24="","",VLOOKUP(G24,REFERENCIA!$A$1:$B$14,2,0)) -> TIPO B | I24: FISCALIZACION A DESTIEMPO
A25: EL BOSQUE | B25: INVERSIONES LAS PATRONAS, C.A | C25: 320 | D25: 46121 | E25: RECEPCION | F25: SUB VICTOR SALCEDO | G25: RECEPCIÓN SIN AUTORIZACIÓN DE CMF. | H25: =IF(G25="","",VLOOKUP(G25,REFERENCIA!$A$1:$B$14,2,0)) -> TIPO E | I25: RECEPCION ELIMINADA EN APP | J25: 1913.1
A26: EL BOSQUE | B26: AGROPECUARIA PUNTA LARGA, C.A| | C26: 2958 | D26: 46125 | E26: RECEPCION | F26: SUB VIRGILIO ARAUJO | G26: PRODUCTO O SKU DUPLICADO. | H26: =IF(G26="","",VLOOKUP(G26,REFERENCIA!$A$1:$B$14,2,0)) -> TIPO B | I26: SKU DUPLICADO
A27: TUCACAS | B27: ALIMENTOS POLAR COMERCIAL, C.A | C27: 8031306009 | D27: 46127 | E27: RECEPCION | F27: SUB GENESIS COBOS | G27: RECEPCIÓN SIN AUTORIZACIÓN DE CMF. | H27: =IF(G27="","",VLOOKUP(G27,REFERENCIA!$A$1:$B$14,2,0)) -> TIPO E | I27: RECEPCION SIN AUTORIZACION DE CMF
A28: TUCACAS | B28: ALIMENTOS POLAR COMERCIAL, C.A | C28: 8031306005 | D28: 46127 | E28: RECEPCION | F28: SUB GENESIS COBOS | G28: RECEPCIÓN SIN AUTORIZACIÓN DE CMF. | H28: =IF(G28="","",VLOOKUP(G28,REFERENCIA!$A$1:$B$14,2,0)) -> TIPO E | I28: RECEPCION SIN AUTORIZACION DE CMF
A29: TUCACAS | B29: ALIMENTOS POLAR COMERCIAL, C.A | C29: 8031306007 | D29: 46127 | E29: RECEPCION | F29: SUB GENESIS COBOS | G29: RECEPCIÓN SIN AUTORIZACIÓN DE CMF. | H29: =IF(G29="","",VLOOKUP(G29,REFERENCIA!$A$1:$B$14,2,0)) -> TIPO E | I29: RECEPCION SIN AUTORIZACION DE CMF
A30: TUCACAS | B30: ALIMENTOS POLAR COMERCIAL, C.A | C30: 8031306008 | D30: 46127 | E30: RECEPCION | F30: SUB GENESIS COBOS | G30: RECEPCIÓN SIN AUTORIZACIÓN DE CMF. | H30: =IF(G30="","",VLOOKUP(G30,REFERENCIA!$A$1:$B$14,2,0)) -> TIPO E | I30: RECEPCION SIN AUTORIZACION DE CMF
A31: TUCACAS | B31: ALIMENTOS POLAR COMERCIAL, C.A | C31: 8031306006 | D31: 46127 | E31: RECEPCION | F31: SUB GENESIS COBOS | G31: RECEPCIÓN SIN AUTORIZACIÓN DE CMF. | H31: =IF(G31="","",VLOOKUP(G31,REFERENCIA!$A$1:$B$14,2,0)) -> TIPO E | I31: RECEPCION SIN AUTORIZACION DE CMF
A32: EL BOSQUE | B32: DISTRIBUIDORA GADUCA,C .A | C32: D-000117245 | D32: 46127 | E32: RECEPCION | F32: SUJB VIRGILIO ARAUJO | G32: NÚMERO DE CONTROL O DOCUMENTO ERRÓNEO. | H32: =IF(G32="","",VLOOKUP(G32,REFERENCIA!$A$1:$B$14,2,0)) -> TIPO A | I32: NUMERO DE CONTROL INCORRECTO
A33: NAGUANAGUA | B33: INVERSIONES AGROPECUARIA JEANDAVID, C.A | C33: 18352 | D33: 46128 | E33: RECEPCION | F33: LPCP VALERIA LAMEDA | G33: NÚMERO DE CONTROL O DOCUMENTO ERRÓNEO. | H33: =IF(G33="","",VLOOKUP(G33,REFERENCIA!$A$1:$B$14,2,0)) -> TIPO A | I33: NUMERO DE CONTROL INCORRECTO
A34: EL BOSQUE | B34: YEFFERSON MORGADO | C34: 125346 | D34: 46132 | E34: RECEPCION | F34: SUB VIRGILIO ARAUJO | G34: NÚMERO DE CONTROL O DOCUMENTO ERRÓNEO. | H34: =IF(G34="","",VLOOKUP(G34,REFERENCIA!$A$1:$B$14,2,0)) -> TIPO A | I34: NUMERO DE CONTROL INCORRECTO
A35: EL BOSQUE | B35: SUPLIDORA EL VIGIA | C35: 6067 | D35: 46132 | E35: RECEPCION | F35: SUB VIRGILIO ARAUJO | G35: NÚMERO DE CONTROL O DOCUMENTO ERRÓNEO. | H35: =IF(G35="","",VLOOKUP(G35,REFERENCIA!$A$1:$B$14,2,0)) -> TIPO A | I35: NUMERO DE CONTROL INCORRECTO
A36: NAGUANAGUA | B36: DISTRIBUIDORA PARADIS FRESH, C.A | C36: 23975 | D36: 46133 | E36: RECEPCION | F36: PCP JOSE MALUENGA | G36: DIFERENCIA ENTRE CANTIDAD FISCALIZADA Y DOCUMENTO. | H36: =IF(G36="","",VLOOKUP(G36,REFERENCIA!$A$1:$B$14,2,0)) -> TIPO D | I36: FALTANTE DE 4 UND DE ESPINACA DE 200GR, 7264.04 | J36: 15.03
A37: TUCACAS | B37: INVERSIONES LAS PATRONAS, C.A | C37: 529 | D37: 46134 | E37: RECEPCION | F37: SUB GENESIS COBOS | G37: DIFERENCIA ENTRE CANTIDAD FISCALIZADA Y DOCUMENTO. | H37: =IF(G37="","",VLOOKUP(G37,REFERENCIA!$A$1:$B$14,2,0)) -> TIPO D | I37: FALTANTE 2.6KG DE MANDARINA, 6283.42 | J37: 13
A38: TUCACAS | B38: NEOPAPEL, C.A | C38: 804 | D38: 23/04/026 | E38: RECEPCION | F38: SUB GENESIS COBOS | G38: DIFERENCIA ENTRE CANTIDAD FISCALIZADA Y DOCUMENTO. | H38: =IF(G38="","",VLOOKUP(G38,REFERENCIA!$A$1:$B$14,2,0)) -> TIPO D | I38: NOTA AL DORSO, 1 UND DE PACK PAW PATROL/SORPRESAS 4301.60 | J38: 8.89
A39: EL BOSQUE | B39: INVERSIONES LAS PATRONAS, C.A | C39: 773 | D39: 46135 | E39: RECEPCION | F39: SUB MARIANGEL GRATEROL | G39: RECEPCIÓN SIN AUTORIZACIÓN DE CMF. | H39: =IF(G39="","",VLOOKUP(G39,REFERENCIA!$A$1:$B$14,2,0)) -> TIPO E | I39: RECEPCION SIN AUTORIZACION DE CMF
A40: EL BOSQUE | B40: INVERSIONES LAS PATRONAS, C.A | C40: 773 | D40: 46135 | E40: RECEPCION | F40: SUB MARIANGEL GRATEROL | G40: DIFERENCIA ENTRE CANTIDAD FISCALIZADA Y DOCUMENTO. | H40: =IF(G40="","",VLOOKUP(G40,REFERENCIA!$A$1:$B$14,2,0)) -> TIPO D | I40: FALTANTE DE 1.5KG DE TOPOCHO VERDE 916.65 | J40: 1.89
...

Sheet Hoja1

Sheet REFERENCIA
A1: NÚMERO DE CONTROL O DOCUMENTO ERRÓNEO. | B1: TIPO A
A2: FALTA SELLO, FIRMA O CÉDULA. | B2: TIPO A
A3: DOCUMENTO NO LEGIBLE | B3: TIPO A
A4: DOCUMENTACIÓN ERRÓNEA | B4: TIPO B
A5: FISCALIZACIÓN A DESTIEMPO | B5: TIPO B
A6: PRODUCTO O SKU DUPLICADO. | B6: TIPO B
A7: RECEPCIÓN FUERA DE VISUAL / CON OBSTRUCCIÓN. | B7: TIPO B
A8: FISCALIZACIÓN CON USUARIO NO CORRESPONDIENTE | B8: TIPO C
A9: ERROR DE KG EN TARA. | B9: TIPO C
A10: PRODUCTO O SKU NO PERTENECE A LA RECEPCIÓN. | B10: TIPO C
A11: NO FISCALIZÓ UNO O VARIOS PRODUCTOS | B11: TIPO C
A12: NO SE INDICÓ DIFERENCIA AL DORSO DE LA FACTURA. | B12: TIPO D
... A14: RECEPCIÓN SIN AUTORIZACIÓN DE CMF. | B14: TIPO E
